<?xml version="1.0"?>
<robot name="hinowa"> 
<!--
 <link name="world" />
  <joint name="world_joint" type="fixed">
    <origin rpy="1.57071 0 0"/>
    <parent link="world"/>
    <child link="base_link"/>
  </joint>
-->
<!-- uncomment for reference to aruco_mapping topic -->

<!--
 <link name="camera_link">
    <collision>
      <origin xyz="0 0 0" rpy="0 0 0"/>
      <geometry>
    <box size="0.160 0.105 0.170"/>
      </geometry>
    </collision>
    <visual>
      <origin xyz="0 0 0" rpy="0 0 0"/>
      <geometry>
    <box size="0.160 0.105 0.170"/>
      </geometry>
    </visual>
 </link>

 <joint name="dummy_joint" type="fixed">
    <origin xyz="0 0 0" rpy="1.57071 1.57071 0"/>
    <parent link="dummy"/>
    <child link="camera_link"/>
 </joint>

 <joint name="camera_joint" type="fixed">
    <origin xyz="0 0 -0.2" rpy="0 0 0"/>
    <parent link="camera_link"/>
    <child link="base_link"/>
 </joint>
-->
<!-- rpy="1.57071 1.57071 0"/>  (commented alt for camera_joint origin)-->

  <link name="anchor"/>

 <joint name="anchor_joint" type="fixed">
    <origin xyz="0.0 0.0 0.0" rpy="0 0 0"/>
    <parent link="anchor"/>
    <child link="base_link"/>
 </joint>

<!--ALL OTHER URDF MODELLING -->
  <link name="base_link">
    <visual>
	<origin xyz="0 0 0" rpy="0 0 0"/>
      <geometry>
        <mesh filename="package://hinowa_description/meshes/rotated_models/base_link.stl" scale="0.001 0.001 0.001"/>
      </geometry>
    </visual>
    <collision>
	<origin xyz="0 0 0" rpy="0 0 0"/>-->
	<geometry>
	  <mesh filename="package://hinowa_description/meshes/rotated_models/base_link.stl" scale="0.001 0.001 0.001"/>
	</geometry>
    </collision>
  </link>

  <link name="link_1">
  <visual>
    <geometry>
      <mesh filename="package://hinowa_description/meshes/rotated_models/link_1.stl" scale="0.001 0.001 0.001"/>
    </geometry>
  </visual>
  <collision>
    <geometry>
      <mesh filename="package://hinowa_description/meshes/rotated_models/link_1.stl" scale="0.001 0.001 0.001"/>
    </geometry>
  </collision>
  </link>

  <joint name="joint_1" type="revolute">
    <origin xyz="0.0 0 0.583" rpy="0 0 0"/>
    <limit lower="-2.61799" upper="2.61799" effort="100" velocity = "0.2053333333"/> <!-- lower: -2.61799, upper 2.61799-->
    <!-- <dynamics damping = "1000.0"/> -->
    <axis xyz="0 0 1"/>
    <parent link="base_link"/>
    <child link="link_1"/>
  </joint>

  <link name="link_2">
  <visual>
    <origin xyz="0.0 0.0 0.0" rpy="0 0 0"/>
    <geometry>
      <mesh filename="package://hinowa_description/meshes/rotated_models/link_2.stl" scale="0.001 0.001 0.001"/>
    </geometry>
  </visual>
  <collision>
    <origin xyz="0.0 0.0 0.0" rpy="0 0 0"/>
    <geometry>
      <mesh filename="package://hinowa_description/meshes/rotated_models/link_2.stl" scale="0.001 0.001 0.001"/>
    </geometry>
  </collision>
<!--   
      <inertial>
      <origin xyz="-0.6 0 -0.1732" rpy="1.849963 0 -1.57071"/>
      <mass value="100"/>
      <inertia  ixx="21.542" ixy="0" ixz="0" iyy="20.448" iyz="5.968" izz="2.065"/> 
   </inertial>
-->
  </link>
<!--
  <joint name="joint_2" type="revolute">
    <origin xyz="0.565 0 0.795" rpy="0 0 0"/>
    <axis xyz="0 1 0"/>
    <limit lower="0" upper="1.22173" effort="100" velocity = "1.0" />
    <parent link="link_1"/>
    <child link="link_2"/>
  </joint>
-->
  <joint name="joint_2" type="fixed">
    <origin xyz="0 -0.550224 0.767144" rpy="0 0 0"/>
  <!--  <axis xyz="0 1 0"/>-->
    <limit effort="100" velocity = "1.0" />
    <parent link="link_1"/>
    <child link="link_2"/>
  </joint>

  <link name="link_3">
  <visual>
    <origin xyz="0 0 0" rpy="0 0 0"/>
    <geometry>
      <mesh filename="package://hinowa_description/meshes/rotated_models/link_3.stl" scale="0.001 0.001 0.001"/>
    </geometry>
  </visual>
  <collision>
    <origin xyz="0 0 0" rpy="0 0 0"/>
    <geometry>
      <mesh filename="package://hinowa_description/meshes/rotated_models/link_3.stl" scale="0.001 0.001 0.001"/>
    </geometry>
  </collision>
  </link>

  <joint name="joint_3" type="fixed">
    <axis xyz="1 0 0"/>
    <origin xyz="0 1.067325 -0.266114" rpy="0 0 0"/>
    <limit effort="100" velocity = "1.0" />
    <parent link="link_2"/>
    <child link="link_3"/>
  </joint>

  <link name="link_4">
  <visual>
    <origin xyz="0 0 0" rpy="0 0 0"/>
    <geometry>
      <mesh filename="package://hinowa_description/meshes/rotated_models/link_4.stl" scale="0.001 0.001 0.001"/>
    </geometry>
  </visual>
  <collision>
    <origin xyz="0 0 0" rpy="0 0 0"/>
    <geometry>
      <mesh filename="package://hinowa_description/meshes/rotated_models/link_4.stl" scale="0.001 0.001 0.001"/>
    </geometry>
  </collision>
  </link>

  <joint name="joint_4" type="revolute">
    <origin xyz="0 0.090 0.460"/>
    <axis xyz="1 0 0"/>
    <limit lower="-1.385791" upper="0" effort="100" velocity = "0.1483870968"/><!---1.406735-->
    <!-- <dynamics damping = "1000.0"/> -->
    <parent link="link_3"/>
    <child link="link_4"/>
  </joint>

  <link name="link_5">
  <visual>
    <origin xyz="0 0 0" rpy="0 0 0"/>
    <geometry>
      <mesh filename="package://hinowa_description/meshes/rotated_models/link_5.stl" scale="0.001 0.001 0.001"/>
    </geometry>
  </visual>
  <collision>
    <origin xyz="0 0 0" rpy="0 0 0"/>
    <geometry>
      <mesh filename="package://hinowa_description/meshes/rotated_models/link_5.stl" scale="0.001 0.001 0.001"/>
    </geometry>
  </collision>
  </link>

  <joint name="joint_5" type="revolute">
    <origin xyz="0 -2.307028 -0.661530" rpy="0 0 0"/>
    <axis xyz="1 0 0"/>
    <limit lower="0" upper="1.385791" effort="100" velocity = "0.1483870968"/> <!---1.406735-->
    <!-- <dynamics damping = "1000.0"/> -->
    <parent link="link_4"/>
    <child link="link_5"/>
    <mimic joint="joint_4" multiplier="-1" offset="0"/>
  </joint>

  <link name="link_6">
  <visual>
    <origin xyz="0 0 0" rpy="0 0 0"/>
    <geometry>
      <mesh filename="package://hinowa_description/meshes/rotated_models/link_6.stl" scale="0.001 0.001 0.001"/>
    </geometry>
  </visual>
  <collision>
    <origin xyz="0 0 0" rpy="0 0 0"/>
    <geometry>
      <mesh filename="package://hinowa_description/meshes/rotated_models/link_6.stl" scale="0.001 0.001 0.001"/>
    </geometry>
  </collision>
  </link>

  <joint name="joint_6" type="revolute">
    <origin xyz="0 -0.09 0.750" rpy="0 0 0"/>
    <axis xyz="1 0 0"/>
    <limit lower="0" upper="1.3439" effort="100" velocity = "0.1595238095"/> <!--1.30159-->
    <!-- <dynamics damping = "1000.0"/> -->
    <parent link="link_5"/>
    <child link="link_6"/>
  </joint>


  <link name="link_7">
  <visual>
    <origin xyz="0 0 0" rpy="0 0 0"/>
    <geometry>
      <mesh filename="package://hinowa_description/meshes/rotated_models/link_7_cable.stl" scale="0.001 0.001 0.001"/>
    </geometry>
  </visual>
  <collision>
    <origin xyz="0 0 0" rpy="0 0 0"/>
    <geometry>
      <mesh filename="package://hinowa_description/meshes/rotated_models/link_7_cable.stl" scale="0.001 0.001 0.001"/>
    </geometry>
  </collision>
  </link>

  <joint name="joint_7" type="prismatic">
    <origin xyz="0 2.735 0" rpy="0 0 0"/>
    <axis xyz="0 1 0"/>
    <limit lower="0" upper="1.854" effort="100" velocity = "0.1267808219"/>
    <!-- <dynamics damping = "1000.0"/> -->
    <parent link="link_6"/>
    <child link="link_7"/>
  </joint>

  <link name="link_8">
  <visual>
    <origin xyz="0 0 0" rpy="0 0 0"/>
    <geometry>
      <mesh filename="package://hinowa_description/meshes/rotated_models/link_8.stl" scale="0.001 0.001 0.001"/>
    </geometry>
  </visual>
  <collision>
    <origin xyz="0 0 0" rpy="0 0 0"/>
    <geometry>
      <mesh filename="package://hinowa_description/meshes/rotated_models/link_8_collision.stl" scale="0.001 0.001 0.001"/>
    </geometry>
  </collision>
  </link>

  <joint name="joint_8" type="revolute">
    <origin xyz="0 0.05 -0.07" rpy="0 0 0"/> <!-- 0 0.120 0.170 -->
    <axis xyz="1 0 0"/>
    <limit lower="0.0" upper="1.439897" effort="100" velocity = "0.2383333333"/><!-- 1.39626 -->
    <!-- <dynamics damping = "1000.0"/> -->
    <parent link="link_7"/>
    <child link="link_8"/>
  </joint>

  <link name="link_9">
  <visual>
    <origin xyz="0 0 0" rpy="0 0 0"/>
    <geometry>
      <mesh filename="package://hinowa_description/meshes/rotated_models/link_9.stl" scale="0.001 0.001 0.001"/>
    </geometry>
  </visual>
  <collision>
    <origin xyz="0 0 0" rpy="0 0 0"/>
    <geometry>
      <mesh filename="package://hinowa_description/meshes/rotated_models/link_9_collision.stl" scale="0.001 0.001 0.001"/>
    </geometry>
  </collision>
</link>

  <joint name="joint_9" type="revolute">
    <origin xyz="0 0.223361 -1.280668" rpy="0 0 0"/>
    <axis xyz="1 0 0"/>
    <limit lower="-1.439897" upper="0.0" effort="100" velocity = "0.2383333333"/><!-- -1.39626 -->
    <!-- <dynamics damping = "1000.0"/> -->
    <parent link="link_8"/>
    <child link="link_9"/>
    <mimic joint="joint_8" multiplier="-1" offset="0.0"/>-->
  </joint>

 <link name="control_link">
  <visual>
    <origin xyz="0 0 0" rpy="0 0 0"/>
    <geometry>
      <mesh filename="package://hinowa_description/meshes/rotated_models/control_link.stl" scale="0.001 0.001 0.001"/>
    </geometry>
  </visual>
  <collision>
    <origin xyz="0 0 0" rpy="0 0 0"/>
    <geometry>
      <mesh filename="package://hinowa_description/meshes/rotated_models/control_link.stl" scale="0.001 0.001 0.001"/>
    </geometry>
  </collision>
 </link>

  <joint name="joint_control" type="fixed">
    <!--<origin xyz="0.120 0.120 0.190" rpy="0 0 3.14159"/> -->
    <origin xyz="0.12 0.0 0.0" rpy="0 0 3.14159"/>  
    <axis xyz="1 0 0"/>
    <!--<limit lower="-1.30159" upper="0" effort="100" velocity = "0.1595238095"/> -->
    <parent link="end_bottom"/>
    <child link="control_link"/>
    <!--<mimic joint="joint_6" multiplier="-1" offset="0.0"/>-->
  </joint>

 <link name="end_bottom">
  <visual>
    <origin xyz="0 0 0" rpy="0 0 0"/>
    <geometry>
      <mesh filename="package://hinowa_description/meshes/rotated_models/end_bottom.stl" scale="0.001 0.001 0.001"/>
    </geometry>
  </visual>
  <collision>
    <origin xyz="0 0 0" rpy="0 0 0"/>
    <geometry>
      <mesh filename="package://hinowa_description/meshes/rotated_models/end_bottom.stl" scale="0.001 0.001 0.001"/>
    </geometry>
  </collision>
 </link>

  <joint name="joint_end_bottom" type="revolute">
    <origin xyz="0 0.120 0.190" rpy="0 0 0"/>
    <axis xyz="1 0 0"/>
    <limit lower="-1.30159" upper="0" effort="100" velocity = "0.1595238095"/>
    <parent link="link_9"/>
    <child link="end_bottom"/>
    <mimic joint="joint_6" multiplier="-1" offset="0.0"/>-->
  </joint>

 <link name="end_middle">
  <visual>
    <origin xyz="0 0 0" rpy="0 0 0"/>
    <geometry>
      <mesh filename="package://hinowa_description/meshes/rotated_models/end_middle.stl" scale="0.001 0.001 0.001"/>
    </geometry>
  </visual>
  <collision>
    <origin xyz="0 0 0" rpy="0 0 0"/>
    <geometry>
      <mesh filename="package://hinowa_description/meshes/rotated_models/end_middle.stl" scale="0.001 0.001 0.001"/>
    </geometry>
  </collision>
 </link>

  <joint name="joint_end_middle" type="revolute">
    <origin xyz="0 0.475 0.300" rpy="0 0 0"/>
    <axis xyz="0 0 1"/>
    <limit lower="-0.523599" upper="0.523599" effort="100" velocity = "1.0" />
    <parent link="end_bottom"/>
    <child link="end_middle"/>
    <!--<mimic joint="joint_1" multiplier="-1" offset="0.0"/> -->
  </joint>

 <link name="end_top">
  <visual>
    <origin xyz="0 0 0" rpy="0 0 0"/>
    <geometry>
      <mesh filename="package://hinowa_description/meshes/rotated_models/end_top_no_rollers.stl" scale="0.001 0.001 0.001"/>
    </geometry>
  </visual>
  <collision>
    <origin xyz="0 0 0" rpy="0 0 0"/>
    <geometry>
      <mesh filename="package://hinowa_description/meshes/rotated_models/end_top_no_rollers.stl" scale="0.001 0.001 0.001"/>
    </geometry>
  </collision>
 </link>

  <joint name="joint_end_top" type="fixed">
    <origin xyz="0.00 0 0.00" rpy="0 0 0"/>
    <axis xyz="1 0 0"/>
    <limit effort="100" velocity = "1.0" />
    <parent link="end_middle"/>
    <child link="end_top"/>
    <!-- <mimic joint="joint_1" multiplier="-1" offset="-1.57071"/> -->
  </joint>

  <link name="end">
  <visual>
    <origin xyz="0 0 0" rpy="0 0 0"/>
    <geometry>
      <box size="0.01 0.01 0.01"/>
    </geometry>
  </visual>
  <collision>
    <origin xyz="0 0 0" rpy="0 0 0"/>
    <geometry>
      <box size="0.0001 0.0001 0.0001"/>
    </geometry>
  </collision>
  </link>

  <joint name="end_joint" type="fixed">
    <origin rpy="0 0 0" xyz="0 0.410 0.045"/>
    <axis xyz="1 0 0"/>
    <!--<limit lower="-0.349066" upper="0.349066" effort="100" velocity = "1.0" /> --> <!-- +-20deg -->
    <limit effort="100" velocity = "1.0" /> -->
    <parent link="end_top"/>
    <child link="end"/>
  </joint>

  <link name="camera">
  <visual>
    <origin xyz="0 0 0" rpy="0 0 0"/>
    <geometry>
      <box size="0.01 0.01 0.01"/>
    </geometry>
  </visual>
  <collision>
    <origin xyz="0 0 0" rpy="0 0 0"/>
    <geometry>
      <box size="0.0001 0.0001 0.0001"/>
    </geometry>
  </collision>
  </link>

  <joint name="camera_joint" type="fixed">
    <origin rpy="-1.57071 0.0 0.0" xyz="0 0.295 0.834"/>
    <axis xyz="1 0 0"/>
    <limit effort="100" velocity = "1.0" />
    <parent link="end_bottom"/>
    <child link="camera"/>
  </joint>

</robot>



